{"nbformat":4,"nbformat_minor":0,"metadata":{"colab":{"provenance":[],"authorship_tag":"ABX9TyO0l72BdvdvApGgUDpdKqcD"},"kernelspec":{"name":"python3","display_name":"Python 3"},"language_info":{"name":"python"}},"cells":[{"cell_type":"code","source":["!kaggle datasets download -d emmarex/plantdisease"],"metadata":{"colab":{"base_uri":"https://localhost:8080/"},"id":"aVWxmbBoF7uQ","executionInfo":{"status":"ok","timestamp":1722318593443,"user_tz":-330,"elapsed":1316,"user":{"displayName":"Rajnish chaube","userId":"17722137216091949762"}},"outputId":"c6bcecee-6a58-4a78-98ac-c88e15ec1d48"},"execution_count":8,"outputs":[{"output_type":"stream","name":"stdout","text":["Dataset URL: https://www.kaggle.com/datasets/emmarex/plantdisease\n","License(s): unknown\n","plantdisease.zip: Skipping, found more recently modified local copy (use --force to force download)\n"]}]},{"cell_type":"code","source":["!unzip plantdisease.zip -d dataset"],"metadata":{"collapsed":true,"colab":{"base_uri":"https://localhost:8080/"},"id":"jnGtFXYlITQS","executionInfo":{"status":"ok","timestamp":1722318626205,"user_tz":-330,"elapsed":14656,"user":{"displayName":"Rajnish chaube","userId":"17722137216091949762"}},"outputId":"5227991e-7e04-4f45-a5fe-ae37797aac2f"},"execution_count":10,"outputs":[{"output_type":"stream","name":"stdout","text":["Archive:  plantdisease.zip\n","replace dataset/PlantVillage/Pepper__bell___Bacterial_spot/0022d6b7-d47c-4ee2-ae9a-392a53f48647___JR_B.Spot 8964.JPG? [y]es, [n]o, [A]ll, [N]one, [r]ename: "]}]},{"cell_type":"code","execution_count":17,"metadata":{"colab":{"base_uri":"https://localhost:8080/","height":1000},"id":"0V6Q8Gk57AKp","executionInfo":{"status":"error","timestamp":1722320858669,"user_tz":-330,"elapsed":5473,"user":{"displayName":"Rajnish chaube","userId":"17722137216091949762"}},"outputId":"2b4a27e6-87e6-47cd-f40f-7126112b105e"},"outputs":[{"output_type":"stream","name":"stdout","text":["Found 28846 images belonging to 2 classes.\n","Found 7210 images belonging to 2 classes.\n","Epoch 1/25\n"]},{"output_type":"error","ename":"InvalidArgumentError","evalue":"Graph execution error:\n\nDetected at node categorical_crossentropy/softmax_cross_entropy_with_logits defined at (most recent call last):\n  File \"/usr/lib/python3.10/runpy.py\", line 196, in _run_module_as_main\n\n  File \"/usr/lib/python3.10/runpy.py\", line 86, in _run_code\n\n  File \"/usr/local/lib/python3.10/dist-packages/colab_kernel_launcher.py\", line 37, in <module>\n\n  File \"/usr/local/lib/python3.10/dist-packages/traitlets/config/application.py\", line 992, in launch_instance\n\n  File \"/usr/local/lib/python3.10/dist-packages/ipykernel/kernelapp.py\", line 619, in start\n\n  File \"/usr/local/lib/python3.10/dist-packages/tornado/platform/asyncio.py\", line 195, in start\n\n  File \"/usr/lib/python3.10/asyncio/base_events.py\", line 603, in run_forever\n\n  File \"/usr/lib/python3.10/asyncio/base_events.py\", line 1909, in _run_once\n\n  File \"/usr/lib/python3.10/asyncio/events.py\", line 80, in _run\n\n  File \"/usr/local/lib/python3.10/dist-packages/tornado/ioloop.py\", line 685, in <lambda>\n\n  File \"/usr/local/lib/python3.10/dist-packages/tornado/ioloop.py\", line 738, in _run_callback\n\n  File \"/usr/local/lib/python3.10/dist-packages/tornado/gen.py\", line 825, in inner\n\n  File \"/usr/local/lib/python3.10/dist-packages/tornado/gen.py\", line 786, in run\n\n  File \"/usr/local/lib/python3.10/dist-packages/ipykernel/kernelbase.py\", line 361, in process_one\n\n  File \"/usr/local/lib/python3.10/dist-packages/tornado/gen.py\", line 234, in wrapper\n\n  File \"/usr/local/lib/python3.10/dist-packages/ipykernel/kernelbase.py\", line 261, in dispatch_shell\n\n  File \"/usr/local/lib/python3.10/dist-packages/tornado/gen.py\", line 234, in wrapper\n\n  File \"/usr/local/lib/python3.10/dist-packages/ipykernel/kernelbase.py\", line 539, in execute_request\n\n  File \"/usr/local/lib/python3.10/dist-packages/tornado/gen.py\", line 234, in wrapper\n\n  File \"/usr/local/lib/python3.10/dist-packages/ipykernel/ipkernel.py\", line 302, in do_execute\n\n  File \"/usr/local/lib/python3.10/dist-packages/ipykernel/zmqshell.py\", line 539, in run_cell\n\n  File \"/usr/local/lib/python3.10/dist-packages/IPython/core/interactiveshell.py\", line 2975, in run_cell\n\n  File \"/usr/local/lib/python3.10/dist-packages/IPython/core/interactiveshell.py\", line 3030, in _run_cell\n\n  File \"/usr/local/lib/python3.10/dist-packages/IPython/core/async_helpers.py\", line 78, in _pseudo_sync_runner\n\n  File \"/usr/local/lib/python3.10/dist-packages/IPython/core/interactiveshell.py\", line 3257, in run_cell_async\n\n  File \"/usr/local/lib/python3.10/dist-packages/IPython/core/interactiveshell.py\", line 3473, in run_ast_nodes\n\n  File \"/usr/local/lib/python3.10/dist-packages/IPython/core/interactiveshell.py\", line 3553, in run_code\n\n  File \"<ipython-input-17-995651f86c8d>\", line 53, in <cell line: 53>\n\n  File \"/usr/local/lib/python3.10/dist-packages/keras/src/utils/traceback_utils.py\", line 65, in error_handler\n\n  File \"/usr/local/lib/python3.10/dist-packages/keras/src/engine/training.py\", line 1807, in fit\n\n  File \"/usr/local/lib/python3.10/dist-packages/keras/src/engine/training.py\", line 1401, in train_function\n\n  File \"/usr/local/lib/python3.10/dist-packages/keras/src/engine/training.py\", line 1384, in step_function\n\n  File \"/usr/local/lib/python3.10/dist-packages/keras/src/engine/training.py\", line 1373, in run_step\n\n  File \"/usr/local/lib/python3.10/dist-packages/keras/src/engine/training.py\", line 1151, in train_step\n\n  File \"/usr/local/lib/python3.10/dist-packages/keras/src/engine/training.py\", line 1209, in compute_loss\n\n  File \"/usr/local/lib/python3.10/dist-packages/keras/src/engine/compile_utils.py\", line 277, in __call__\n\n  File \"/usr/local/lib/python3.10/dist-packages/keras/src/losses.py\", line 143, in __call__\n\n  File \"/usr/local/lib/python3.10/dist-packages/keras/src/losses.py\", line 270, in call\n\n  File \"/usr/local/lib/python3.10/dist-packages/keras/src/losses.py\", line 2221, in categorical_crossentropy\n\n  File \"/usr/local/lib/python3.10/dist-packages/keras/src/backend.py\", line 5579, in categorical_crossentropy\n\nlogits and labels must be broadcastable: logits_size=[32,5] labels_size=[32,2]\n\t [[{{node categorical_crossentropy/softmax_cross_entropy_with_logits}}]] [Op:__inference_train_function_3059]","traceback":["\u001b[0;31m---------------------------------------------------------------------------\u001b[0m","\u001b[0;31mInvalidArgumentError\u001b[0m                      Traceback (most recent call last)","\u001b[0;32m<ipython-input-17-995651f86c8d>\u001b[0m in \u001b[0;36m<cell line: 53>\u001b[0;34m()\u001b[0m\n\u001b[1;32m     51\u001b[0m \u001b[0;34m\u001b[0m\u001b[0m\n\u001b[1;32m     52\u001b[0m \u001b[0;31m# Model Training\u001b[0m\u001b[0;34m\u001b[0m\u001b[0;34m\u001b[0m\u001b[0m\n\u001b[0;32m---> 53\u001b[0;31m history = model.fit(\n\u001b[0m\u001b[1;32m     54\u001b[0m     \u001b[0mtrain_generator\u001b[0m\u001b[0;34m,\u001b[0m\u001b[0;34m\u001b[0m\u001b[0;34m\u001b[0m\u001b[0m\n\u001b[1;32m     55\u001b[0m     \u001b[0mepochs\u001b[0m\u001b[0;34m=\u001b[0m\u001b[0;36m25\u001b[0m\u001b[0;34m,\u001b[0m\u001b[0;34m\u001b[0m\u001b[0;34m\u001b[0m\u001b[0m\n","\u001b[0;32m/usr/local/lib/python3.10/dist-packages/keras/src/utils/traceback_utils.py\u001b[0m in \u001b[0;36merror_handler\u001b[0;34m(*args, **kwargs)\u001b[0m\n\u001b[1;32m     68\u001b[0m             \u001b[0;31m# To get the full stack trace, call:\u001b[0m\u001b[0;34m\u001b[0m\u001b[0;34m\u001b[0m\u001b[0m\n\u001b[1;32m     69\u001b[0m             \u001b[0;31m# `tf.debugging.disable_traceback_filtering()`\u001b[0m\u001b[0;34m\u001b[0m\u001b[0;34m\u001b[0m\u001b[0m\n\u001b[0;32m---> 70\u001b[0;31m             \u001b[0;32mraise\u001b[0m \u001b[0me\u001b[0m\u001b[0;34m.\u001b[0m\u001b[0mwith_traceback\u001b[0m\u001b[0;34m(\u001b[0m\u001b[0mfiltered_tb\u001b[0m\u001b[0;34m)\u001b[0m \u001b[0;32mfrom\u001b[0m \u001b[0;32mNone\u001b[0m\u001b[0;34m\u001b[0m\u001b[0;34m\u001b[0m\u001b[0m\n\u001b[0m\u001b[1;32m     71\u001b[0m         \u001b[0;32mfinally\u001b[0m\u001b[0;34m:\u001b[0m\u001b[0;34m\u001b[0m\u001b[0;34m\u001b[0m\u001b[0m\n\u001b[1;32m     72\u001b[0m             \u001b[0;32mdel\u001b[0m \u001b[0mfiltered_tb\u001b[0m\u001b[0;34m\u001b[0m\u001b[0;34m\u001b[0m\u001b[0m\n","\u001b[0;32m/usr/local/lib/python3.10/dist-packages/tensorflow/python/eager/execute.py\u001b[0m in \u001b[0;36mquick_execute\u001b[0;34m(op_name, num_outputs, inputs, attrs, ctx, name)\u001b[0m\n\u001b[1;32m     51\u001b[0m   \u001b[0;32mtry\u001b[0m\u001b[0;34m:\u001b[0m\u001b[0;34m\u001b[0m\u001b[0;34m\u001b[0m\u001b[0m\n\u001b[1;32m     52\u001b[0m     \u001b[0mctx\u001b[0m\u001b[0;34m.\u001b[0m\u001b[0mensure_initialized\u001b[0m\u001b[0;34m(\u001b[0m\u001b[0;34m)\u001b[0m\u001b[0;34m\u001b[0m\u001b[0;34m\u001b[0m\u001b[0m\n\u001b[0;32m---> 53\u001b[0;31m     tensors = pywrap_tfe.TFE_Py_Execute(ctx._handle, device_name, op_name,\n\u001b[0m\u001b[1;32m     54\u001b[0m                                         inputs, attrs, num_outputs)\n\u001b[1;32m     55\u001b[0m   \u001b[0;32mexcept\u001b[0m \u001b[0mcore\u001b[0m\u001b[0;34m.\u001b[0m\u001b[0m_NotOkStatusException\u001b[0m \u001b[0;32mas\u001b[0m \u001b[0me\u001b[0m\u001b[0;34m:\u001b[0m\u001b[0;34m\u001b[0m\u001b[0;34m\u001b[0m\u001b[0m\n","\u001b[0;31mInvalidArgumentError\u001b[0m: Graph execution error:\n\nDetected at node categorical_crossentropy/softmax_cross_entropy_with_logits defined at (most recent call last):\n  File \"/usr/lib/python3.10/runpy.py\", line 196, in _run_module_as_main\n\n  File \"/usr/lib/python3.10/runpy.py\", line 86, in _run_code\n\n  File \"/usr/local/lib/python3.10/dist-packages/colab_kernel_launcher.py\", line 37, in <module>\n\n  File \"/usr/local/lib/python3.10/dist-packages/traitlets/config/application.py\", line 992, in launch_instance\n\n  File \"/usr/local/lib/python3.10/dist-packages/ipykernel/kernelapp.py\", line 619, in start\n\n  File \"/usr/local/lib/python3.10/dist-packages/tornado/platform/asyncio.py\", line 195, in start\n\n  File \"/usr/lib/python3.10/asyncio/base_events.py\", line 603, in run_forever\n\n  File \"/usr/lib/python3.10/asyncio/base_events.py\", line 1909, in _run_once\n\n  File \"/usr/lib/python3.10/asyncio/events.py\", line 80, in _run\n\n  File \"/usr/local/lib/python3.10/dist-packages/tornado/ioloop.py\", line 685, in <lambda>\n\n  File \"/usr/local/lib/python3.10/dist-packages/tornado/ioloop.py\", line 738, in _run_callback\n\n  File \"/usr/local/lib/python3.10/dist-packages/tornado/gen.py\", line 825, in inner\n\n  File \"/usr/local/lib/python3.10/dist-packages/tornado/gen.py\", line 786, in run\n\n  File \"/usr/local/lib/python3.10/dist-packages/ipykernel/kernelbase.py\", line 361, in process_one\n\n  File \"/usr/local/lib/python3.10/dist-packages/tornado/gen.py\", line 234, in wrapper\n\n  File \"/usr/local/lib/python3.10/dist-packages/ipykernel/kernelbase.py\", line 261, in dispatch_shell\n\n  File \"/usr/local/lib/python3.10/dist-packages/tornado/gen.py\", line 234, in wrapper\n\n  File \"/usr/local/lib/python3.10/dist-packages/ipykernel/kernelbase.py\", line 539, in execute_request\n\n  File \"/usr/local/lib/python3.10/dist-packages/tornado/gen.py\", line 234, in wrapper\n\n  File \"/usr/local/lib/python3.10/dist-packages/ipykernel/ipkernel.py\", line 302, in do_execute\n\n  File \"/usr/local/lib/python3.10/dist-packages/ipykernel/zmqshell.py\", line 539, in run_cell\n\n  File \"/usr/local/lib/python3.10/dist-packages/IPython/core/interactiveshell.py\", line 2975, in run_cell\n\n  File \"/usr/local/lib/python3.10/dist-packages/IPython/core/interactiveshell.py\", line 3030, in _run_cell\n\n  File \"/usr/local/lib/python3.10/dist-packages/IPython/core/async_helpers.py\", line 78, in _pseudo_sync_runner\n\n  File \"/usr/local/lib/python3.10/dist-packages/IPython/core/interactiveshell.py\", line 3257, in run_cell_async\n\n  File \"/usr/local/lib/python3.10/dist-packages/IPython/core/interactiveshell.py\", line 3473, in run_ast_nodes\n\n  File \"/usr/local/lib/python3.10/dist-packages/IPython/core/interactiveshell.py\", line 3553, in run_code\n\n  File \"<ipython-input-17-995651f86c8d>\", line 53, in <cell line: 53>\n\n  File \"/usr/local/lib/python3.10/dist-packages/keras/src/utils/traceback_utils.py\", line 65, in error_handler\n\n  File \"/usr/local/lib/python3.10/dist-packages/keras/src/engine/training.py\", line 1807, in fit\n\n  File \"/usr/local/lib/python3.10/dist-packages/keras/src/engine/training.py\", line 1401, in train_function\n\n  File \"/usr/local/lib/python3.10/dist-packages/keras/src/engine/training.py\", line 1384, in step_function\n\n  File \"/usr/local/lib/python3.10/dist-packages/keras/src/engine/training.py\", line 1373, in run_step\n\n  File \"/usr/local/lib/python3.10/dist-packages/keras/src/engine/training.py\", line 1151, in train_step\n\n  File \"/usr/local/lib/python3.10/dist-packages/keras/src/engine/training.py\", line 1209, in compute_loss\n\n  File \"/usr/local/lib/python3.10/dist-packages/keras/src/engine/compile_utils.py\", line 277, in __call__\n\n  File \"/usr/local/lib/python3.10/dist-packages/keras/src/losses.py\", line 143, in __call__\n\n  File \"/usr/local/lib/python3.10/dist-packages/keras/src/losses.py\", line 270, in call\n\n  File \"/usr/local/lib/python3.10/dist-packages/keras/src/losses.py\", line 2221, in categorical_crossentropy\n\n  File \"/usr/local/lib/python3.10/dist-packages/keras/src/backend.py\", line 5579, in categorical_crossentropy\n\nlogits and labels must be broadcastable: logits_size=[32,5] labels_size=[32,2]\n\t [[{{node categorical_crossentropy/softmax_cross_entropy_with_logits}}]] [Op:__inference_train_function_3059]"]}],"source":["import tensorflow as tf\n","from tensorflow.keras.preprocessing.image import ImageDataGenerator\n","from tensorflow.keras.models import Sequential\n","from tensorflow.keras.layers import Conv2D, MaxPooling2D, Flatten, Dense, Dropout\n","\n","# Data Preprocessing\n","datagen = ImageDataGenerator(\n","    rescale=1./255,\n","    validation_split=0.2,\n","    rotation_range=20,\n","    width_shift_range=0.2,\n","    height_shift_range=0.2,\n","    shear_range=0.2,\n","    zoom_range=0.2,\n","    horizontal_flip=True,\n","    fill_mode='nearest'\n",")\n","\n","train_generator = datagen.flow_from_directory(\n","    'dataset',\n","    target_size=(128, 128),\n","    batch_size=32,\n","    class_mode='categorical',\n","    subset='training'\n",")\n","\n","validation_generator = datagen.flow_from_directory(\n","    'dataset',\n","    target_size=(128, 128),\n","    batch_size=32,\n","    class_mode='categorical',\n","    subset='validation'\n",")\n","\n","# Model Building\n","model = Sequential([\n","    Conv2D(32, (3, 3), activation='relu', input_shape=(128, 128, 3)),\n","    MaxPooling2D((2, 2)),\n","    Conv2D(64, (3, 3), activation='relu'),\n","    MaxPooling2D((2, 2)),\n","    Conv2D(128, (3, 3), activation='relu'),\n","    MaxPooling2D((2, 2)),\n","    Flatten(),\n","    Dense(512, activation='relu'),\n","    Dropout(0.5),\n","    Dense(5, activation='softmax')  # Assuming 5 classes of diseases\n","])\n","\n","# Model Compilation\n","model.compile(optimizer='adam', loss='categorical_crossentropy', metrics=['accuracy'])\n","\n","# Model Training\n","history = model.fit(\n","    train_generator,\n","    epochs=25,\n","    validation_data=validation_generator\n",")\n","\n","# Model Evaluation\n","test_loss, test_acc = model.evaluate(validation_generator)\n","print(f\"Test accuracy: {test_acc}\")\n","\n","# Save the model\n","model.save('16bbb84a-b078-4c74-8ab0-872ac7240052___UF.GRC_BS_Lab Leaf 8605.jpg')\n"]},{"cell_type":"code","source":["from flask import Flask, request, jsonify\n","import tensorflow as tf\n","from tensorflow.keras.preprocessing import image\n","import numpy as np\n","\n","app = Flask(__name__)\n","model = tf.keras.models.load_model('16bbb84a-b078-4c74-8ab0-872ac7240052___UF.GRC_BS_Lab Leaf 8605.jpg')\n","\n","def preprocess_image(img):\n","    img = img.resize((128, 128))\n","    img = image.img_to_array(img)\n","    img = np.expand_dims(img, axis=0)\n","    img = img / 255.0\n","    return img\n","\n","@app.route('/predict', methods=['POST'])\n","def predict():\n","    img = request.files['file']\n","    img = Image.open(img)\n","    img = preprocess_image(img)\n","\n","    prediction = model.predict(img)\n","    predicted_class = np.argmax(prediction, axis=1)\n","\n","    return jsonify({'prediction': int(predicted_class)})\n","\n","if __name__ == '__main__':\n","    app.run(debug=True)\n"],"metadata":{"colab":{"base_uri":"https://localhost:8080/","height":370},"id":"24sNnF8g77dO","executionInfo":{"status":"error","timestamp":1722320162305,"user_tz":-330,"elapsed":519,"user":{"displayName":"Rajnish chaube","userId":"17722137216091949762"}},"outputId":"b1b6d16a-b979-47f1-950e-d82c527af2e6"},"execution_count":13,"outputs":[{"output_type":"error","ename":"OSError","evalue":"No file or directory found at plantdisease.zip.h5","traceback":["\u001b[0;31m---------------------------------------------------------------------------\u001b[0m","\u001b[0;31mOSError\u001b[0m                                   Traceback (most recent call last)","\u001b[0;32m<ipython-input-13-d899c48687b2>\u001b[0m in \u001b[0;36m<cell line: 7>\u001b[0;34m()\u001b[0m\n\u001b[1;32m      5\u001b[0m \u001b[0;34m\u001b[0m\u001b[0m\n\u001b[1;32m      6\u001b[0m \u001b[0mapp\u001b[0m \u001b[0;34m=\u001b[0m \u001b[0mFlask\u001b[0m\u001b[0;34m(\u001b[0m\u001b[0m__name__\u001b[0m\u001b[0;34m)\u001b[0m\u001b[0;34m\u001b[0m\u001b[0;34m\u001b[0m\u001b[0m\n\u001b[0;32m----> 7\u001b[0;31m \u001b[0mmodel\u001b[0m \u001b[0;34m=\u001b[0m \u001b[0mtf\u001b[0m\u001b[0;34m.\u001b[0m\u001b[0mkeras\u001b[0m\u001b[0;34m.\u001b[0m\u001b[0mmodels\u001b[0m\u001b[0;34m.\u001b[0m\u001b[0mload_model\u001b[0m\u001b[0;34m(\u001b[0m\u001b[0;34m'plantdisease.zip.h5'\u001b[0m\u001b[0;34m)\u001b[0m\u001b[0;34m\u001b[0m\u001b[0;34m\u001b[0m\u001b[0m\n\u001b[0m\u001b[1;32m      8\u001b[0m \u001b[0;34m\u001b[0m\u001b[0m\n\u001b[1;32m      9\u001b[0m \u001b[0;32mdef\u001b[0m \u001b[0mpreprocess_image\u001b[0m\u001b[0;34m(\u001b[0m\u001b[0mimg\u001b[0m\u001b[0;34m)\u001b[0m\u001b[0;34m:\u001b[0m\u001b[0;34m\u001b[0m\u001b[0;34m\u001b[0m\u001b[0m\n","\u001b[0;32m/usr/local/lib/python3.10/dist-packages/keras/src/saving/saving_api.py\u001b[0m in \u001b[0;36mload_model\u001b[0;34m(filepath, custom_objects, compile, safe_mode, **kwargs)\u001b[0m\n\u001b[1;32m    260\u001b[0m \u001b[0;34m\u001b[0m\u001b[0m\n\u001b[1;32m    261\u001b[0m     \u001b[0;31m# Legacy case.\u001b[0m\u001b[0;34m\u001b[0m\u001b[0;34m\u001b[0m\u001b[0m\n\u001b[0;32m--> 262\u001b[0;31m     return legacy_sm_saving_lib.load_model(\n\u001b[0m\u001b[1;32m    263\u001b[0m         \u001b[0mfilepath\u001b[0m\u001b[0;34m,\u001b[0m \u001b[0mcustom_objects\u001b[0m\u001b[0;34m=\u001b[0m\u001b[0mcustom_objects\u001b[0m\u001b[0;34m,\u001b[0m \u001b[0mcompile\u001b[0m\u001b[0;34m=\u001b[0m\u001b[0mcompile\u001b[0m\u001b[0;34m,\u001b[0m \u001b[0;34m**\u001b[0m\u001b[0mkwargs\u001b[0m\u001b[0;34m\u001b[0m\u001b[0;34m\u001b[0m\u001b[0m\n\u001b[1;32m    264\u001b[0m     )\n","\u001b[0;32m/usr/local/lib/python3.10/dist-packages/keras/src/utils/traceback_utils.py\u001b[0m in \u001b[0;36merror_handler\u001b[0;34m(*args, **kwargs)\u001b[0m\n\u001b[1;32m     68\u001b[0m             \u001b[0;31m# To get the full stack trace, call:\u001b[0m\u001b[0;34m\u001b[0m\u001b[0;34m\u001b[0m\u001b[0m\n\u001b[1;32m     69\u001b[0m             \u001b[0;31m# `tf.debugging.disable_traceback_filtering()`\u001b[0m\u001b[0;34m\u001b[0m\u001b[0;34m\u001b[0m\u001b[0m\n\u001b[0;32m---> 70\u001b[0;31m             \u001b[0;32mraise\u001b[0m \u001b[0me\u001b[0m\u001b[0;34m.\u001b[0m\u001b[0mwith_traceback\u001b[0m\u001b[0;34m(\u001b[0m\u001b[0mfiltered_tb\u001b[0m\u001b[0;34m)\u001b[0m \u001b[0;32mfrom\u001b[0m \u001b[0;32mNone\u001b[0m\u001b[0;34m\u001b[0m\u001b[0;34m\u001b[0m\u001b[0m\n\u001b[0m\u001b[1;32m     71\u001b[0m         \u001b[0;32mfinally\u001b[0m\u001b[0;34m:\u001b[0m\u001b[0;34m\u001b[0m\u001b[0;34m\u001b[0m\u001b[0m\n\u001b[1;32m     72\u001b[0m             \u001b[0;32mdel\u001b[0m \u001b[0mfiltered_tb\u001b[0m\u001b[0;34m\u001b[0m\u001b[0;34m\u001b[0m\u001b[0m\n","\u001b[0;32m/usr/local/lib/python3.10/dist-packages/keras/src/saving/legacy/save.py\u001b[0m in \u001b[0;36mload_model\u001b[0;34m(filepath, custom_objects, compile, options)\u001b[0m\n\u001b[1;32m    232\u001b[0m                     \u001b[0;32mif\u001b[0m \u001b[0misinstance\u001b[0m\u001b[0;34m(\u001b[0m\u001b[0mfilepath_str\u001b[0m\u001b[0;34m,\u001b[0m \u001b[0mstr\u001b[0m\u001b[0;34m)\u001b[0m\u001b[0;34m:\u001b[0m\u001b[0;34m\u001b[0m\u001b[0;34m\u001b[0m\u001b[0m\n\u001b[1;32m    233\u001b[0m                         \u001b[0;32mif\u001b[0m \u001b[0;32mnot\u001b[0m \u001b[0mtf\u001b[0m\u001b[0;34m.\u001b[0m\u001b[0mio\u001b[0m\u001b[0;34m.\u001b[0m\u001b[0mgfile\u001b[0m\u001b[0;34m.\u001b[0m\u001b[0mexists\u001b[0m\u001b[0;34m(\u001b[0m\u001b[0mfilepath_str\u001b[0m\u001b[0;34m)\u001b[0m\u001b[0;34m:\u001b[0m\u001b[0;34m\u001b[0m\u001b[0;34m\u001b[0m\u001b[0m\n\u001b[0;32m--> 234\u001b[0;31m                             raise IOError(\n\u001b[0m\u001b[1;32m    235\u001b[0m                                 \u001b[0;34mf\"No file or directory found at {filepath_str}\"\u001b[0m\u001b[0;34m\u001b[0m\u001b[0;34m\u001b[0m\u001b[0m\n\u001b[1;32m    236\u001b[0m                             )\n","\u001b[0;31mOSError\u001b[0m: No file or directory found at plantdisease.zip.h5"]}]},{"cell_type":"code","source":[],"metadata":{"id":"WtKM2Ymm77oH","executionInfo":{"status":"aborted","timestamp":1722318593444,"user_tz":-330,"elapsed":5,"user":{"displayName":"Rajnish chaube","userId":"17722137216091949762"}}},"execution_count":null,"outputs":[]}]}